<?xml version="1.0" encoding="utf-8"?>
<!-- This URDF was automatically created by SolidWorks to URDF Exporter! Originally created by Stephen Brawner (brawner@gmail.com) 
     Commit Version: 1.5.1-0-g916b5db  Build Version: 1.5.7152.31018
     For more information, please see http://wiki.ros.org/sw_urdf_exporter -->
<robot name="conveyor_belt">
	<link name="world" />

	<joint name="fixed" type="fixed">
		<parent link="world"/>
		<child link="belt_visual"/>
		<origin xyz="0.5 0.0 0.7" rpy="0.0 0.0 0"/>
	</joint>

	<link name="belt_visual">
		<inertial>
			<origin xyz="0 0 0" rpy="0 0 0" />
			<mass value="1"/>
			<inertia
				ixx="0.07" ixy="0.0" ixz="0.0"
				iyy="0.40" iyz="0.0"
				izz="0.33"/>
   		</inertial>

		<visual>
			<origin xyz="0 0 0" rpy="0 0 0" />
			<geometry>
				<box size="0.2 1.5 0.05"/>
			</geometry>
		</visual>

		<collision>
			<origin xyz="0 0 0" rpy="0 0 0" />
			<geometry>
				<box size="0.2 1.5 0.05"/>
			</geometry>
		</collision>
	</link>

	<gazebo reference="belt_visual">
        <material>Gazebo/White</material>
    </gazebo>

	<joint name="belt_joint" type="prismatic">
		<origin xyz="0.0 0.0 0.025" rpy="0.0 0.0 0.0"/>
		<parent link="belt_visual"/>
		<child link="belt_moving"/>
		<axis xyz="0 1 0"/>
		<limit lower="0.0" upper="1" effort="1000" velocity="1000"/>
	</joint>

	<link name="belt_moving">
		<inertial>
			<origin xyz="0.0 0.0 0.0" rpy="0.0 0.0 0.0"/>
			<mass value="100"/>
			<inertia ixx="0.0" ixy="0.0" ixz="0.0" iyy="0.0" iyz="0.0" izz="0.0"/>
		</inertial>
		<visual>
			<origin xyz="0.0 0.0 0.0005" rpy="0.0 0.0 0.0"/>
			<geometry>
				<box size="0.2 1.5 0.001"/>
			</geometry>
		</visual>
		<collision>
			<origin xyz="0.0 0.0 0.0005" rpy="0.0 0.0 0.0"/>
			<geometry>
				<box size="0.2 1.5 0.001"/>
			</geometry>
		</collision>
	</link>

	<gazebo reference="belt_moving">
        <material>Gazebo/DarkGrey</material>
    </gazebo>

	<gazebo>
		<plugin name="conveyor_belt_plugin" filename="libROSConveyorBeltPlugin.so">
			<robot_namespace>/</robot_namespace>
			<link>belt_moving</link>
			<power>0</power>
			<max_velocity>1.0</max_velocity>
		</plugin>
	</gazebo>
</robot>